<?xml version="1.0" ?>
<!-- =================================================================================== -->
<!-- |    This document was autogenerated by xacro from robot.xacro                    | -->
<!-- |    EDITING THIS FILE BY HAND IS NOT RECOMMENDED                                 | -->
<!-- =================================================================================== -->
<robot name="z1_description">
  <!-- ros_control plugin -->
  <link name="world"/>
  <joint name="base_static_joint" type="fixed">
    <origin rpy="0 0 0" xyz="0 0 0"/>
    <parent link="world"/>
    <child link="link00"/>
  </joint>
  <link name="link00">
    <visual>
      <origin rpy="0 0 0" xyz="0 0 0"/>
      <geometry>
        <mesh filename="../meshes/z1_Link00.dae" scale="1 1 1"/>
      </geometry>
    </visual>
    <collision>
      <geometry>
        <cylinder length="0.051" radius="0.0325"/>
      </geometry>
      <origin rpy="0 0 0" xyz="0 0 0.0255"/>
    </collision>
    <inertial>
      <origin rpy="0 0 0" xyz="-0.00334984 -0.00013615 0.02495843"/>
      <mass value="0.47247481"/>
      <inertia ixx="0.00037937" ixy="3.5e-07" ixz="1.037e-05" iyy="0.00041521" iyz="9.9e-07" izz="0.00053066"/>
    </inertial>
  </link>
  <joint name="joint1" type="revolute">
    <origin rpy="0 0 0" xyz="0 0 0.0585"/>
    <parent link="link00"/>
    <child link="link01"/>
    <axis xyz="0 0 1"/>
    <dynamics damping="1.0" friction="1.0"/>
    <limit effort="30.0" lower="-2.6179938779914944" upper="2.6179938779914944" velocity="10"/>
  </joint>
  <link name="link01">
    <visual>
      <origin rpy="0 0 0" xyz="0 0 0"/>
      <geometry>
        <mesh filename="../meshes/z1_Link01.dae" scale="1 1 1"/>
      </geometry>
    </visual>
    <!-- <collision>
            <geometry>
                <cylinder length="${2*motor_height}" radius="${motor_diameter}"/>
            </geometry>
            <origin rpy="0 0 0" xyz="0 0 0"/>
        </collision> -->
    <inertial>
      <origin rpy="0 0 0" xyz="2.47e-06 -0.00025198 0.02317169"/>
      <mass value="0.67332551"/>
      <inertia ixx="0.00128328" ixy="6e-08" ixz="4e-07" iyy="0.00071931" iyz="-5e-07" izz="0.00083936"/>
    </inertial>
  </link>
  <joint name="joint2" type="revolute">
    <origin rpy="0 0 0" xyz="0 0 0.045"/>
    <parent link="link01"/>
    <child link="link02"/>
    <axis xyz="0 1 0"/>
    <dynamics damping="2.0" friction="2.0"/>
    <limit effort="60.0" lower="0.0" upper="3.141592653589793" velocity="10"/>
  </joint>
  <link name="link02">
    <visual>
      <origin rpy="0 0 0" xyz="0 0 0"/>
      <geometry>
        <mesh filename="../meshes/z1_Link02.dae" scale="1 1 1"/>
      </geometry>
    </visual>
    <collision>
      <geometry>
        <cylinder length="0.102" radius="0.0325"/>
      </geometry>
      <origin rpy="1.5707963267948966 0 0" xyz="0 0 0"/>
    </collision>
    <collision>
      <geometry>
        <cylinder length="0.235" radius="0.0225"/>
      </geometry>
      <origin rpy="0 1.5707963267948966 0" xyz="-0.16249999999999998 0 0"/>
    </collision>
    <collision>
      <geometry>
        <cylinder length="0.051" radius="0.0325"/>
      </geometry>
      <origin rpy="1.5707963267948966 0 0" xyz="-0.35 0 0"/>
    </collision>
    <inertial>
      <origin rpy="0 0 0" xyz="-0.11012601 0.00240029 0.00158266"/>
      <mass value="1.19132258"/>
      <inertia ixx="0.00102138" ixy="-0.00062358" ixz="-5.13e-06" iyy="0.02429457" iyz="2.1e-06" izz="0.02466114"/>
    </inertial>
  </link>
  <joint name="joint3" type="revolute">
    <origin rpy="0 0 0" xyz="-0.35 0 0"/>
    <parent link="link02"/>
    <child link="link03"/>
    <axis xyz="0 1 0"/>
    <dynamics damping="1.0" friction="1.0"/>
    <limit effort="30.0" lower="-4.782202150464463" upper="0.0" velocity="10"/>
  </joint>
  <link name="link03">
    <visual>
      <origin rpy="0 0 0" xyz="0 0 0"/>
      <geometry>
        <mesh filename="../meshes/z1_Link03.dae" scale="1 1 1"/>
      </geometry>
    </visual>
    <collision>
      <geometry>
        <cylinder length="0.116" radius="0.02"/>
      </geometry>
      <origin rpy="0 1.5707963267948966 0" xyz="0.128 0 0.055"/>
    </collision>
    <collision>
      <geometry>
        <cylinder length="0.059" radius="0.0325"/>
      </geometry>
      <origin rpy="0 1.5707963267948966 0" xyz="0.2205 0 0.055"/>
    </collision>
    <inertial>
      <origin rpy="0 0 0" xyz="0.10609208 -0.00541815 0.03476383"/>
      <mass value="0.83940874"/>
      <inertia ixx="0.00108061" ixy="8.669e-05" ixz="0.00208102" iyy="0.00954238" iyz="1.332e-05" izz="0.00886621"/>
    </inertial>
  </link>
  <joint name="joint4" type="revolute">
    <origin rpy="0 0 0" xyz="0.218 0 0.057"/>
    <parent link="link03"/>
    <child link="link04"/>
    <axis xyz="0 1 0"/>
    <dynamics damping="1.0" friction="1.0"/>
    <limit effort="30.0" lower="-1.7453292519943295" upper="1.5707963267948966" velocity="10"/>
  </joint>
  <link name="link04">
    <visual>
      <origin rpy="0 0 0" xyz="0 0 0"/>
      <geometry>
        <mesh filename="../meshes/z1_Link04.dae" scale="1 1 1"/>
      </geometry>
    </visual>
    <collision>
      <geometry>
        <cylinder length="0.073" radius="0.0325"/>
      </geometry>
      <origin rpy="1.5707963267948966 0 0" xyz="0.0472 0 0"/>
    </collision>
    <inertial>
      <origin rpy="0 0 0" xyz="0.04366681 0.00364738 -0.00170192"/>
      <mass value="0.56404563"/>
      <inertia ixx="0.00031576" ixy="-8.13e-05" ixz="-4.091e-05" iyy="0.00092996" iyz="5.96e-06" izz="0.00097912"/>
    </inertial>
  </link>
  <joint name="joint5" type="revolute">
    <origin rpy="0 0 0" xyz="0.07 0.0 0.0"/>
    <parent link="link04"/>
    <child link="link05"/>
    <axis xyz="0 0 1"/>
    <dynamics damping="1.0" friction="1.0"/>
    <limit effort="30.0" lower="-1.7278759594743864" upper="1.7278759594743864" velocity="10"/>
  </joint>
  <link name="link05">
    <visual>
      <origin rpy="0 0 0" xyz="0 0 0"/>
      <geometry>
        <mesh filename="../meshes/z1_Link05.dae" scale="1 1 1"/>
      </geometry>
    </visual>
    <inertial>
      <origin rpy="0 0 0" xyz="0.03121533 0.0 0.00646316"/>
      <mass value="0.38938492"/>
      <inertia ixx="0.00017605" ixy="-4e-07" ixz="-5.689e-05" iyy="0.00055896" iyz="1.3e-07" izz="0.0005386"/>
    </inertial>
  </link>
  <joint name="joint6" type="revolute">
    <origin rpy="0 0 0" xyz="0.0492 0.0 0.0"/>
    <parent link="link05"/>
    <child link="link06"/>
    <axis xyz="1 0 0"/>
    <dynamics damping="1.0" friction="1.0"/>
    <limit effort="30.0" lower="-2.792526803190927" upper="2.792526803190927" velocity="10"/>
  </joint>
  <link name="link06">
    <visual>
      <origin rpy="0 0 0" xyz="0 0 0"/>
      <geometry>
        <mesh filename="../meshes/z1_Link06.dae" scale="1 1 1"/>
      </geometry>
    </visual>
    <collision>
      <geometry>
        <cylinder length="0.051" radius="0.0325"/>
      </geometry>
      <origin rpy="0 1.5707963267948966 0" xyz="0.0255 0 0"/>
    </collision>
    <inertial>
      <origin rpy="0 0 0" xyz="0.0241569 -0.00017355 -0.00143876"/>
      <mass value="0.28875807"/>
      <inertia ixx="0.00018328" ixy="-1.22e-06" ixz="-5.4e-07" iyy="0.0001475" iyz="-8e-08" izz="0.0001468"/>
    </inertial>
  </link>
  <joint name="joint7" type="fixed">
    <origin rpy="0 0 1.5708" xyz="0.0492 0.0 0.0"/>
    <parent link="link06"/>
    <child link="r_wrist_roll"/>
    <axis xyz="1 0 0"/>
<!--    <dynamics damping="1.0" friction="1.0"/>-->
<!--    <limit effort="30.0" lower="-3.14159" upper="2.792526803190927" velocity="10"/>-->
  </joint>
  <link
    name="r_wrist_roll">
    <inertial>
      <origin
        xyz="0.00104845406000195 -0.00226416454894157 0.0450349944872783"
        rpy="0 0 0" />
      <mass
        value="0.259209493453575" />
      <inertia
        ixx="0.000182758540304299"
        ixy="7.20471014756865E-06"
        ixz="-1.07021916234917E-05"
        iyy="0.000165660832733147"
        iyz="9.21835242195824E-06"
        izz="0.000136275746104948" />
    </inertial>
    <visual>
      <origin
        xyz="0 0 0"
        rpy="0 0 0" />
      <geometry>
        <mesh
          filename="../meshes/r_wrist_roll.STL" />
      </geometry>
      <material
        name="">
        <color
          rgba="0.466666666666667 0.72156862745098 1 1" />
      </material>
    </visual>
    <collision>
      <origin
        xyz="0 0 0"
        rpy="0 0 0" />
      <geometry>
        <mesh
          filename="../meshes/r_wrist_roll.STL" />
      </geometry>
    </collision>
  </link>
  <link
    name="r_fing_one_ax_one">
    <inertial>
      <origin
        xyz="0.0188362743733334 0.00294333468827893 4.14269071513651E-06"
        rpy="0 0 0" />
      <mass
        value="0.00852335938362883" />
      <inertia
        ixx="8.476854504723E-07"
        ixy="2.3559819323796E-08"
        ixz="1.1915741710678E-10"
        iyy="2.08568526490774E-06"
        iyz="-1.75042535589845E-10"
        izz="1.9852845189272E-06" />
    </inertial>
    <visual>
      <origin
        xyz="0 0 0"
        rpy="0 0 0" />
      <geometry>
        <mesh
          filename="../meshes/r_fing_one_ax_one.STL" />
      </geometry>
      <material
        name="">
        <color
          rgba="0.792156862745098 0.819607843137255 0.933333333333333 1" />
      </material>
    </visual>
    <collision>
      <origin
        xyz="0 0 0"
        rpy="0 0 0" />
      <geometry>
        <mesh
          filename="../meshes/r_fing_one_ax_one.STL" />
      </geometry>
    </collision>
  </link>
  <joint
    name="r_fing_one_ax_one"
    type="revolute">
    <origin
      xyz="0.0330562331149497 -0.0994 0.013"
      rpy="1.5708 0. -1.5708" />
    <parent
      link="r_wrist_roll" />
    <child
      link="r_fing_one_ax_one" />
    <axis
      xyz="0 -1 0" />
    <limit
      lower="0"
      upper="1.57"
      effort="2"
      velocity="9.27" />
  </joint>
  <link
    name="r_fing_one_ax_two">
    <inertial>
      <origin
        xyz="0.0249283649813485 0.0070628980485378 -6.06019024740334E-07"
        rpy="0 0 0" />
      <mass
        value="0.0127580341635526" />
      <inertia
        ixx="9.31814807142041E-07"
        ixy="-8.47247723772167E-07"
        ixz="-1.66817023003657E-10"
        iyy="2.78639503737818E-06"
        iyz="-6.56550866497719E-12"
        izz="2.98728431870261E-06" />
    </inertial>
    <visual>
      <origin
        xyz="0 0 0"
        rpy="0 0 0" />
      <geometry>
        <mesh
          filename="../meshes/r_fing_one_ax_two.STL" />
      </geometry>
      <material
        name="">
        <color
          rgba="0.792156862745098 0.819607843137255 0.933333333333333 1" />
      </material>
    </visual>
    <collision>
      <origin
        xyz="0 0 0"
        rpy="0 0 0" />
      <geometry>
        <mesh
          filename="../meshes/r_fing_one_ax_two.STL" />
      </geometry>
    </collision>
  </link>
  <joint
    name="r_fing_one_ax_two"
    type="revolute">
    <origin
      xyz="0.0450000000000061 0.00500000000003697 0"
      rpy="0 0 0" />
    <parent
      link="r_fing_one_ax_one" />
    <child
      link="r_fing_one_ax_two" />
    <axis
      xyz="0 0 1" />
    <limit
      lower="0"
      upper="1.57"
      effort="2"
      velocity="9.27" />
  </joint>
  <link
    name="r_fing_two_ax_one">
    <inertial>
      <origin
        xyz="0.0238362748906265 -0.00205666604194735 4.1400835137928E-06"
        rpy="0 0 0" />
      <mass
        value="0.0085233600529091" />
      <inertia
        ixx="8.47685582935135E-07"
        ixy="2.35598997040366E-08"
        ixz="1.19299637871993E-10"
        iyy="2.08568541193829E-06"
        iyz="-1.75284053647776E-10"
        izz="1.98528453816723E-06" />
    </inertial>
    <visual>
      <origin
        xyz="0 0 0"
        rpy="0 0 0" />
      <geometry>
        <mesh
          filename="../meshes/r_fing_two_ax_one.STL" />
      </geometry>
      <material
        name="">
        <color
          rgba="0.792156862745098 0.819607843137255 0.933333333333333 1" />
      </material>
    </visual>
    <collision>
      <origin
        xyz="0 0 0"
        rpy="0 0 0" />
      <geometry>
        <mesh
          filename="../meshes/r_fing_two_ax_one.STL" />
      </geometry>
    </collision>
  </link>
  <joint
    name="r_fing_two_ax_one"
    type="revolute">
    <origin
      xyz="0.0174998953381831 -0.0347057099186331 0.0943999999999999"
      rpy="-0.148889947609497 -1.57079631189374 1.29589402872594" />
    <parent
      link="r_wrist_roll" />
    <child
      link="r_fing_two_ax_one" />
    <axis
      xyz="0 0 1" />
    <limit
      lower="0"
      upper="1.57"
      effort="2"
      velocity="9.27" />
  </joint>
  <link
    name="r_fing_two_ax_two">
    <inertial>
      <origin
        xyz="0.025870742525118 0.00141855138464378 -6.07075500258514E-07"
        rpy="0 0 0" />
      <mass
        value="0.0127580310141361" />
      <inertia
        ixx="6.58288705375617E-07"
        ixy="-3.68423252423282E-07"
        ixz="-1.63892950762011E-10"
        iyy="3.05991918012616E-06"
        iyz="3.03422179476033E-11"
        izz="2.98728250346117E-06" />
    </inertial>
    <visual>
      <origin
        xyz="0 0 0"
        rpy="0 0 0" />
      <geometry>
        <mesh
          filename="../meshes/r_fing_two_ax_two.STL" />
      </geometry>
      <material
        name="">
        <color
          rgba="0.792156862745098 0.819607843137255 0.933333333333333 1" />
      </material>
    </visual>
    <collision>
      <origin
        xyz="0 0 0"
        rpy="0 0 0" />
      <geometry>
        <mesh
          filename="../meshes/r_fing_two_ax_two.STL" />
      </geometry>
    </collision>
  </link>
  <joint
    name="r_fing_two_ax_two"
    type="revolute">
    <origin
      xyz="0.0500000000000064 0 0"
      rpy="0 0 0.221314442348394" />
    <parent
      link="r_fing_two_ax_one" />
    <child
      link="r_fing_two_ax_two" />
    <axis
      xyz="0 0 1" />
    <limit
      lower="0"
      upper="1.57"
      effort="2"
      velocity="9.27" />
  </joint>
  <link
    name="r_thumb_ax_one">
    <inertial>
      <origin
        xyz="0.0238362760231771 -0.00205666778924551 4.14292559614005E-06"
        rpy="0 0 0" />
      <mass
        value="0.00852336182304319" />
      <inertia
        ixx="8.47685500686259E-07"
        ixy="2.35599713325613E-08"
        ixz="1.1904981123733E-10"
        iyy="2.0856852523159E-06"
        iyz="-1.75142252780147E-10"
        izz="1.98528484654138E-06" />
    </inertial>
    <visual>
      <origin
        xyz="0 0 0"
        rpy="0 0 0" />
      <geometry>
        <mesh
          filename="../meshes/r_thumb_ax_one.STL" />
      </geometry>
      <material
        name="">
        <color
          rgba="0.792156862745098 0.819607843137255 0.933333333333333 1" />
      </material>
    </visual>
    <collision>
      <origin
        xyz="0 0 0"
        rpy="0 0 0" />
      <geometry>
        <mesh
          filename="../meshes/r_thumb_ax_one.STL" />
      </geometry>
    </collision>
  </link>
  <joint
    name="r_thumb_ax_one"
    type="revolute">
    <origin
      xyz="-0.0452197958110675 0.0167512229355485 0.0711004794480864"
      rpy="1.5707963267949 -0.872664625997169 3.09408301615884" />
    <parent
      link="r_wrist_roll" />
    <child
      link="r_thumb_ax_one" />
    <axis
      xyz="0 0 1" />
    <limit
      lower="0"
      upper="1.57"
      effort="2"
      velocity="9.27" />
  </joint>
  <link
    name="r_thumb_ax_two">
    <inertial>
      <origin
        xyz="0.0258646947799948 0.00152510353102547 -6.04346597599115E-07"
        rpy="0 0 0" />
      <mass
        value="0.0127580400309577" />
      <inertia
        ixx="6.61364665416618E-07"
        ixy="-3.78304410339619E-07"
        ixz="-1.65024283554354E-10"
        iyy="3.05684847347107E-06"
        iyz="2.90471402039158E-11"
        izz="2.98728718567267E-06" />
    </inertial>
    <visual>
      <origin
        xyz="0 0 0"
        rpy="0 0 0" />
      <geometry>
        <mesh
          filename="../meshes/r_thumb_ax_two.STL" />
      </geometry>
      <material
        name="">
        <color
          rgba="0.792156862745098 0.819607843137255 0.933333333333333 1" />
      </material>
    </visual>
    <collision>
      <origin
        xyz="0 0 0"
        rpy="0 0 0" />
      <geometry>
        <mesh
          filename="../meshes/r_thumb_ax_two.STL" />
      </geometry>
    </collision>
  </link>
  <joint
    name="r_thumb_ax_two"
    type="revolute">
    <origin
      xyz="0.0500000000000064 0 0"
      rpy="0 0 0.217195372304988" />
    <parent
      link="r_thumb_ax_one" />
    <child
      link="r_thumb_ax_two" />
    <axis
      xyz="0 0 1" />
    <limit
      lower="0"
      upper="1.57"
      effort="2"
      velocity="9.27" />
  </joint>
</robot>
